<?xml version="1.0" ?>
<!-- =================================================================================== -->
<!-- |    This document was autogenerated by xacro from /home/siddharth/capstone_ws/src/Agribot_V2/agribot_v4_description/urdf/agribot_v4.xacro | -->
<!-- |    EDITING THIS FILE BY HAND IS NOT RECOMMENDED                                 | -->
<!-- =================================================================================== -->
<robot name="agribot_v4">
    <material name="silver_default">
        <color rgba="0.700 0.700 0.700 1.000" />
    </material>
    <material name="steel_satin">
        <color rgba="0.6274509803921569 0.6274509803921569 0.6274509803921569 1.0" />
    </material>
    <material name="opaque272727">
        <color rgba="0.10588235294117647 0.10588235294117647 0.10588235294117647 1.0" />
    </material>
    <transmission name="front_right_steer_tran">
        <type>transmission_interface/SimpleTransmission</type>
        <joint name="front_right_steer">
            <hardwareInterface>hardware_interface/PositionJointInterface</hardwareInterface>
        </joint>
        <actuator name="front_right_steer_actr">
            <hardwareInterface>hardware_interface/PositionJointInterface</hardwareInterface>
            <mechanicalReduction>1</mechanicalReduction>
        </actuator>
    </transmission>
    <transmission name="front_left_steer_tran">
        <type>transmission_interface/SimpleTransmission</type>
        <joint name="front_left_steer">
            <hardwareInterface>hardware_interface/PositionJointInterface</hardwareInterface>
        </joint>
        <actuator name="front_left_steer_actr">
            <hardwareInterface>hardware_interface/PositionJointInterface</hardwareInterface>
            <mechanicalReduction>1</mechanicalReduction>
        </actuator>
    </transmission>
    <transmission name="back_right_steer_tran">
        <type>transmission_interface/SimpleTransmission</type>
        <joint name="back_right_steer">
            <hardwareInterface>hardware_interface/PositionJointInterface</hardwareInterface>
        </joint>
        <actuator name="back_right_steer_actr">
            <hardwareInterface>hardware_interface/PositionJointInterface</hardwareInterface>
            <mechanicalReduction>1</mechanicalReduction>
        </actuator>
    </transmission>
    <transmission name="back_left_steer_tran">
        <type>transmission_interface/SimpleTransmission</type>
        <joint name="back_left_steer">
            <hardwareInterface>hardware_interface/PositionJointInterface</hardwareInterface>
        </joint>
        <actuator name="back_left_steer_actr">
            <hardwareInterface>hardware_interface/PositionJointInterface</hardwareInterface>
            <mechanicalReduction>1</mechanicalReduction>
        </actuator>
    </transmission>
    <transmission name="front_right_drive_tran">
        <type>transmission_interface/SimpleTransmission</type>
        <joint name="front_right_drive">
            <hardwareInterface>hardware_interface/EffortJointInterface</hardwareInterface>
        </joint>
        <actuator name="front_right_drive_actr">
            <hardwareInterface>hardware_interface/EffortJointInterface</hardwareInterface>
            <mechanicalReduction>1</mechanicalReduction>
        </actuator>
    </transmission>
    <transmission name="front_left_drive_tran">
        <type>transmission_interface/SimpleTransmission</type>
        <joint name="front_left_drive">
            <hardwareInterface>hardware_interface/EffortJointInterface</hardwareInterface>
        </joint>
        <actuator name="front_left_drive_actr">
            <hardwareInterface>hardware_interface/EffortJointInterface</hardwareInterface>
            <mechanicalReduction>1</mechanicalReduction>
        </actuator>
    </transmission>
    <transmission name="back_left_drive_tran">
        <type>transmission_interface/SimpleTransmission</type>
        <joint name="back_left_drive">
            <hardwareInterface>hardware_interface/EffortJointInterface</hardwareInterface>
        </joint>
        <actuator name="back_left_drive_actr">
            <hardwareInterface>hardware_interface/EffortJointInterface</hardwareInterface>
            <mechanicalReduction>1</mechanicalReduction>
        </actuator>
    </transmission>
    <transmission name="back_right_drive_tran">
        <type>transmission_interface/SimpleTransmission</type>
        <joint name="back_right_drive">
            <hardwareInterface>hardware_interface/EffortJointInterface</hardwareInterface>
        </joint>
        <actuator name="back_right_drive_actr">
            <hardwareInterface>hardware_interface/EffortJointInterface</hardwareInterface>
            <mechanicalReduction>1</mechanicalReduction>
        </actuator>
    </transmission>
    <transmission name="base_twist_tran">
        <type>transmission_interface/SimpleTransmission</type>
        <joint name="base_twist">
            <hardwareInterface>hardware_interface/PositionJointInterface</hardwareInterface>
        </joint>
        <actuator name="base_twist_actr">
            <hardwareInterface>hardware_interface/PositionJointInterface</hardwareInterface>
            <mechanicalReduction>1</mechanicalReduction>
        </actuator>
    </transmission>
    <transmission name="shoulder_tran">
        <type>transmission_interface/SimpleTransmission</type>
        <joint name="shoulder">
            <hardwareInterface>hardware_interface/PositionJointInterface</hardwareInterface>
        </joint>
        <actuator name="shoulder_actr">
            <hardwareInterface>hardware_interface/PositionJointInterface</hardwareInterface>
            <mechanicalReduction>1</mechanicalReduction>
        </actuator>
    </transmission>
    <transmission name="elbow_tran">
        <type>transmission_interface/SimpleTransmission</type>
        <joint name="elbow">
            <hardwareInterface>hardware_interface/PositionJointInterface</hardwareInterface>
        </joint>
        <actuator name="elbow_actr">
            <hardwareInterface>hardware_interface/PositionJointInterface</hardwareInterface>
            <mechanicalReduction>1</mechanicalReduction>
        </actuator>
    </transmission>
    <transmission name="wrist_tran">
        <type>transmission_interface/SimpleTransmission</type>
        <joint name="wrist">
            <hardwareInterface>hardware_interface/PositionJointInterface</hardwareInterface>
        </joint>
        <actuator name="wrist_actr">
            <hardwareInterface>hardware_interface/PositionJointInterface</hardwareInterface>
            <mechanicalReduction>1</mechanicalReduction>
        </actuator>
    </transmission>
    <transmission name="left_grip_tran">
        <type>transmission_interface/SimpleTransmission</type>
        <joint name="left_grip">
            <hardwareInterface>hardware_interface/PositionJointInterface</hardwareInterface>
        </joint>
        <actuator name="left_grip_actr">
            <hardwareInterface>hardware_interface/PositionJointInterface</hardwareInterface>
            <mechanicalReduction>1</mechanicalReduction>
        </actuator>
    </transmission>
    <transmission name="right_grip_tran">
        <type>transmission_interface/SimpleTransmission</type>
        <joint name="right_grip">
            <hardwareInterface>hardware_interface/PositionJointInterface</hardwareInterface>
        </joint>
        <actuator name="right_grip_actr">
            <hardwareInterface>hardware_interface/PositionJointInterface</hardwareInterface>
            <mechanicalReduction>1</mechanicalReduction>
        </actuator>
    </transmission>
    <!-- <gazebo>
        <plugin filename="libgazebo_ros_control.so" name="control" />
        <plugin name="gazebo_ros_control">
            <robotNamespace>/</robotNamespace>
        </plugin>
    </gazebo> -->
    <gazebo>
  <plugin name="control" filename="libgazebo_ros_control.so"/>
</gazebo>
    <gazebo reference="base_link">
        <material>Gazebo/Silver</material>
        <mu1>0.2</mu1>
        <mu2>0.2</mu2>
        <selfCollide>true</selfCollide>
        <gravity>true</gravity>
    </gazebo>
    <gazebo reference="wheel_steer_v2_1">
        <material>Gazebo/Grey</material>
        <mu1>0.2</mu1>
        <mu2>0.2</mu2>
        <selfCollide>true</selfCollide>
    </gazebo>
    <gazebo reference="wheel_steer_v2_2">
        <material>Gazebo/Grey</material>
        <mu1>0.2</mu1>
        <mu2>0.2</mu2>
        <selfCollide>true</selfCollide>
    </gazebo>
    <gazebo reference="wheel_steer_v2_3">
        <material>Gazebo/Grey</material>
        <mu1>0.2</mu1>
        <mu2>0.2</mu2>
        <selfCollide>true</selfCollide>
    </gazebo>
    <gazebo reference="wheel_steer_v2_4">
        <material>Gazebo/Grey</material>
        <mu1>0.2</mu1>
        <mu2>0.2</mu2>
        <selfCollide>true</selfCollide>
    </gazebo>
    <gazebo reference="wheel_attachment_v5_1">
        <material>Gazebo/Black</material>
        <mu1>100</mu1>
        <mu2>100</mu2>
        <selfCollide>true</selfCollide>
    </gazebo>
    <gazebo reference="wheel_attachment_v5_2">
        <material>Gazebo/Black</material>
        <mu1>100</mu1>
        <mu2>100</mu2>
        <selfCollide>true</selfCollide>
    </gazebo>
    <gazebo reference="wheel_attachment_v5_3">
        <material>Gazebo/Black</material>
        <mu1>100</mu1>
        <mu2>100</mu2>
        <selfCollide>true</selfCollide>
    </gazebo>
    <gazebo reference="wheel_attachment_v5_4">
        <material>Gazebo/Black</material>
        <mu1>100</mu1>
        <mu2>100</mu2>
        <selfCollide>true</selfCollide>
    </gazebo>
    <gazebo reference="camera_mount_v1_1">
        <material>Gazebo/Silver</material>
        <mu1>0.2</mu1>
        <mu2>0.2</mu2>
        <selfCollide>true</selfCollide>
    </gazebo>
    <gazebo reference="kinectv2_v1_1">
        <material>Gazebo/DarkGrey</material>
        <mu1>0.2</mu1>
        <mu2>0.2</mu2>
        <selfCollide>true</selfCollide>
    </gazebo>
    <gazebo reference="rgb_frame" />
    <gazebo reference="base_arm_v2_1">
        <material>Gazebo/Black</material>
        <mu1>0.2</mu1>
        <mu2>0.2</mu2>
        <selfCollide>true</selfCollide>
    </gazebo>
    <gazebo reference="link_1_v3_1">
        <material>Gazebo/Black</material>
        <mu1>0.2</mu1>
        <mu2>0.2</mu2>
        <selfCollide>true</selfCollide>
    </gazebo>
    <gazebo reference="link_2_v1_1">
        <material>Gazebo/Black</material>
        <mu1>0.2</mu1>
        <mu2>0.2</mu2>
        <selfCollide>true</selfCollide>
    </gazebo>
    <gazebo reference="link_3_v2_1">
        <material>Gazebo/Black</material>
        <mu1>0.2</mu1>
        <mu2>0.2</mu2>
        <selfCollide>true</selfCollide>
    </gazebo>
    <gazebo reference="eef_base_v1_1">
        <material>Gazebo/Black</material>
        <mu1>0.2</mu1>
        <mu2>0.2</mu2>
        <selfCollide>true</selfCollide>
    </gazebo>
    <gazebo reference="left_claw_v3_1">
        <material>Gazebo/DarkGrey</material>
        <mu1>0.2</mu1>
        <mu2>0.2</mu2>
        <selfCollide>true</selfCollide>
    </gazebo>
    <gazebo reference="right_claw_v3_1">
        <material>Gazebo/DarkGrey</material>
        <mu1>0.2</mu1>
        <mu2>0.2</mu2>
        <selfCollide>true</selfCollide>
    </gazebo>
    <gazebo reference="ydlidar_x4_v1_1">
        <material>Gazebo/Blue</material>
        <mu1>0.2</mu1>
        <mu2>0.2</mu2>
        <selfCollide>true</selfCollide>
    </gazebo>
    <!-- Lidar -->
    <gazebo reference="ydlidar_x4_v1_1">
        <sensor name="head_hokuyo_sensor" type="ray">
            <pose>0 0 0 0 0 0</pose>
            <visualize>false</visualize>
            <update_rate>40</update_rate>
            <ray>
                <scan>
                    <horizontal>
                        <samples>720</samples>
                        <resolution>1</resolution>
                        <min_angle>-3.1416</min_angle>
                        <max_angle>3.1416</max_angle>
                    </horizontal>
                </scan>
                <range>
                    <min>0.10</min>
                    <max>8.0</max>
                    <resolution>0.01</resolution>
                </range>
                <noise>
                    <type>gaussian</type>
                    <!-- Noise parameters based on published spec for Hokuyo laser
              achieving "+-30mm" accuracy at range < 10m.  A mean of 0.0m and
              stddev of 0.01m will put 99.7% of samples within 0.03m of the true
              reading. -->
                    <mean>0.0</mean>
                    <stddev>0.01</stddev>
                </noise>
            </ray>
            <plugin filename="libgazebo_ros_laser.so" name="gazebo_ros_head_hokuyo_controller">
                <topicName>/scan</topicName>
                <frameName>ydlidar_x4_v1_1</frameName>
            </plugin>
        </sensor>
    </gazebo>
    <!-- Kinect -->
    <gazebo reference="rgb_frame">
        <sensor name="kinectv2_camera" type="depth">
            <update_rate>20</update_rate>
            <camera>
                <horizontal_fov>1.5708</horizontal_fov>
                <image>
                    <width>1920</width>
                    <height>1080</height>
                    <format>R8G8B8</format>
                </image>
                <clip>
                    <near>0.5</near>
                    <far>4.5</far>
                </clip>
            </camera>
            <plugin filename="libgazebo_ros_openni_kinect.so" name="kinectv2_controller">
                <baseline>0.2</baseline>
                <alwaysOn>true</alwaysOn>
                <updateRate>1.0</updateRate>
                <cameraName>kinectv2_ir</cameraName>
                <imageTopicName>/kinectv2/color/image_raw</imageTopicName>
                <cameraInfoTopicName>/kinectv2/color/camera_info</cameraInfoTopicName>
                <depthImageTopicName>/kinectv2/depth/image_raw</depthImageTopicName>
                <depthImageInfoTopicName>/kinectv2/depth/camera_info</depthImageInfoTopicName>
                <pointCloudTopicName>/kinectv2/depth/points</pointCloudTopicName>
                <frameName>optical_frame</frameName>
                <pointCloudCutoff>0.5</pointCloudCutoff>
                <pointCloudCutoffMax>4.5</pointCloudCutoffMax>
                <distortionK1>0.00000001</distortionK1>
                <distortionK2>0.00000001</distortionK2>
                <distortionK3>0.00000001</distortionK3>
                <distortionT1>0.00000001</distortionT1>
                <distortionT2>0.00000001</distortionT2>
                <CxPrime>0</CxPrime>
                <Cx>0</Cx>
                <Cy>0</Cy>
                <focalLength>0</focalLength>
                <hackBaseline>0</hackBaseline>
            </plugin>
        </sensor>
    </gazebo>
    <!-- <gazebo>
        <plugin name="differential_drive_controller" filename="libgazebo_ros_diff_drive.so">

            <updateRate>50</updateRate>

            <leftJoint>front_left_drive</leftJoint>

            <rightJoint>front_right_drive</rightJoint>

            <wheelSeparation>0.48</wheelSeparation>

            <wheelDiameter>0.2</wheelDiameter>

            <wheelAcceleration>1.0</wheelAcceleration>

            <wheelTorque>20</wheelTorque>

            <commandTopic>cmd_vel</commandTopic>

            <odometryTopic>odom</odometryTopic>

            <odometryFrame>odom</odometryFrame>

            <robotBaseFrame>base_link</robotBaseFrame>

            <odometrySource>1</odometrySource>

            <publishWheelTF>false</publishWheelTF>

            <publishOdom>true</publishOdom>

            <publishWheelJointState>true</publishWheelJointState>

            <legacyMode>false</legacyMode>
        </plugin>
    </gazebo> -->
    <gazebo>
        <plugin filename="libgazebo_ros_skid_steer_drive.so" name="skid_steer_drive_controller">
            <updateRate>100.0</updateRate>
            <robotNamespace>/</robotNamespace>
            <leftFrontJoint>front_left_drive</leftFrontJoint>
            <rightFrontJoint>front_right_drive</rightFrontJoint>
            <leftRearJoint>back_left_drive</leftRearJoint>
            <rightRearJoint>back_right_drive</rightRearJoint>
            <wheelSeparation>0.482</wheelSeparation>
            <wheelDiameter>0.2</wheelDiameter>
            <robotBaseFrame>base_link</robotBaseFrame>
            <torque>20</torque>
            <topicName>cmd_vel</topicName>
            <!-- <odometryTopic>odom</odometryTopic>
            <odometryFrame>odom</odometryFrame> -->
            <broadcastTF>true</broadcastTF>
        </plugin>
    </gazebo>
    <link name="base_link">
        <inertial>
            <origin rpy="0 0 0" xyz="0.01610508467278378 -0.048512745473199226 0.353121746597701" />
            <mass value="27.846871515045496" />
            <inertia ixx="2.939866" ixy="0.145869" ixz="0.26679" iyy="3.354179" iyz="-0.819071" izz="2.835372" />
        </inertial>
        <visual>
            <origin rpy="0 0 0" xyz="0 0 0" />
            <geometry>
                <mesh filename="package://agribot_v4_description/meshes/base_link.stl" scale="0.001 0.001 0.001" />
            </geometry>
            <material name="steel_satin" />
        </visual>
        <collision>
            <origin rpy="0 0 0" xyz="0 0 0" />
            <geometry>
                <mesh filename="package://agribot_v4_description/meshes/base_link.stl" scale="0.001 0.001 0.001" />
            </geometry>
        </collision>
    </link>
    <link name="wheel_steer_v2_1">
        <inertial>
            <origin rpy="0 0 0" xyz="0.00021003231190241944 0.05617615621691546 -0.10447321411662486" />
            <mass value="0.5982881054375317" />
            <inertia ixx="0.001675" ixy="-1e-06" ixz="2e-06" iyy="0.001292" iyz="0.000487" izz="0.00052" />
        </inertial>
        <visual>
            <origin rpy="0 0 0" xyz="-0.372581 0.24075 -0.2316" />
            <geometry>
                <mesh filename="package://agribot_v4_description/meshes/wheel_steer_v2_1.stl" scale="0.001 0.001 0.001" />
            </geometry>
            <material name="steel_satin" />
        </visual>
        <collision>
            <origin rpy="0 0 0" xyz="-0.372581 0.24075 -0.2316" />
            <geometry>
                <mesh filename="package://agribot_v4_description/meshes/wheel_steer_v2_1.stl" scale="0.001 0.001 0.001" />
            </geometry>
        </collision>
    </link>
    <link name="wheel_steer_v2_2">
        <inertial>
            <origin rpy="0 0 0" xyz="0.00014346524604108568 -0.056176376182222404 -0.10447293489378814" />
            <mass value="0.5982881054375317" />
            <inertia ixx="0.001675" ixy="1e-06" ixz="2e-06" iyy="0.001292" iyz="-0.000487" izz="0.00052" />
        </inertial>
        <visual>
            <origin rpy="0 0 0" xyz="-0.372522 -0.24115 -0.231574" />
            <geometry>
                <mesh filename="package://agribot_v4_description/meshes/wheel_steer_v2_2.stl" scale="0.001 0.001 0.001" />
            </geometry>
            <material name="steel_satin" />
        </visual>
        <collision>
            <origin rpy="0 0 0" xyz="-0.372522 -0.24115 -0.231574" />
            <geometry>
                <mesh filename="package://agribot_v4_description/meshes/wheel_steer_v2_2.stl" scale="0.001 0.001 0.001" />
            </geometry>
        </collision>
    </link>
    <link name="wheel_steer_v2_3">
        <inertial>
            <origin rpy="0 0 0" xyz="-0.00014774436418335535 0.056176156216906054 -0.10447291646888351" />
            <mass value="0.5982881054375317" />
            <inertia ixx="0.001675" ixy="1e-06" ixz="-2e-06" iyy="0.001292" iyz="0.000487" izz="0.00052" />
        </inertial>
        <visual>
            <origin rpy="0 0 0" xyz="0.371732 0.24115 -0.231126" />
            <geometry>
                <mesh filename="package://agribot_v4_description/meshes/wheel_steer_v2_3.stl" scale="0.001 0.001 0.001" />
            </geometry>
            <material name="steel_satin" />
        </visual>
        <collision>
            <origin rpy="0 0 0" xyz="0.371732 0.24115 -0.231126" />
            <geometry>
                <mesh filename="package://agribot_v4_description/meshes/wheel_steer_v2_3.stl" scale="0.001 0.001 0.001" />
            </geometry>
        </collision>
    </link>
    <link name="wheel_steer_v2_4">
        <inertial>
            <origin rpy="0 0 0" xyz="-0.00014731032191012128 -0.056176376182209053 -0.10447330742333955" />
            <mass value="0.5982881054375317" />
            <inertia ixx="0.001675" ixy="-1e-06" ixz="-2e-06" iyy="0.001292" iyz="-0.000487" izz="0.00052" />
        </inertial>
        <visual>
            <origin rpy="0 0 0" xyz="0.372163 -0.24115 -0.231127" />
            <geometry>
                <mesh filename="package://agribot_v4_description/meshes/wheel_steer_v2_4.stl" scale="0.001 0.001 0.001" />
            </geometry>
            <material name="steel_satin" />
        </visual>
        <collision>
            <origin rpy="0 0 0" xyz="0.372163 -0.24115 -0.231127" />
            <geometry>
                <mesh filename="package://agribot_v4_description/meshes/wheel_steer_v2_4.stl" scale="0.001 0.001 0.001" />
            </geometry>
        </collision>
    </link>
    <link name="wheel_attachment_v5_1">
        <inertial>
            <origin rpy="0 0 0" xyz="4.572659950685676e-07 -0.02018340239780056 5.671483370439656e-08" />
            <mass value="2.8568879657816306" />
            <inertia ixx="0.0105" ixy="0.0" ixz="-0.0" iyy="0.020703" iyz="0.0" izz="0.0105" />
        </inertial>
        <visual>
            <origin rpy="0 0 0" xyz="-0.372842 0.220194 -0.1016" />
            <geometry>
                <mesh filename="package://agribot_v4_description/meshes/wheel_attachment_v5_1.stl" scale="0.001 0.001 0.001" />
            </geometry>
            <material name="steel_satin" />
        </visual>
        <collision>
            <origin rpy="0 0 0" xyz="-0.372842 0.220194 -0.1016" />
            <geometry>
                <mesh filename="package://agribot_v4_description/meshes/wheel_attachment_v5_1.stl" scale="0.001 0.001 0.001" />
            </geometry>
        </collision>
    </link>
    <link name="wheel_attachment_v5_2">
        <inertial>
            <origin rpy="0 0 0" xyz="-4.3366520940946174e-07 0.0201841824324952 3.082717962565873e-07" />
            <mass value="2.8568879657816306" />
            <inertia ixx="0.0105" ixy="0.0" ixz="-0.0" iyy="0.020703" iyz="0.0" izz="0.0105" />
        </inertial>
        <visual>
            <origin rpy="0 0 0" xyz="-0.372701 -0.220593 -0.101574" />
            <geometry>
                <mesh filename="package://agribot_v4_description/meshes/wheel_attachment_v5_2.stl" scale="0.001 0.001 0.001" />
            </geometry>
            <material name="steel_satin" />
        </visual>
        <collision>
            <origin rpy="0 0 0" xyz="-0.372701 -0.220593 -0.101574" />
            <geometry>
                <mesh filename="package://agribot_v4_description/meshes/wheel_attachment_v5_2.stl" scale="0.001 0.001 0.001" />
            </geometry>
        </collision>
    </link>
    <link name="wheel_attachment_v5_3">
        <inertial>
            <origin rpy="0 0 0" xyz="-4.188595414400531e-07 0.020184182432508774 -6.285256151650209e-08" />
            <mass value="2.8568879657816306" />
            <inertia ixx="0.0105" ixy="0.0" ixz="0.0" iyy="0.020703" iyz="0.0" izz="0.0105" />
        </inertial>
        <visual>
            <origin rpy="0 0 0" xyz="0.372346 -0.220593 -0.101127" />
            <geometry>
                <mesh filename="package://agribot_v4_description/meshes/wheel_attachment_v5_3.stl" scale="0.001 0.001 0.001" />
            </geometry>
            <material name="steel_satin" />
        </visual>
        <collision>
            <origin rpy="0 0 0" xyz="0.372346 -0.220593 -0.101127" />
            <geometry>
                <mesh filename="package://agribot_v4_description/meshes/wheel_attachment_v5_3.stl" scale="0.001 0.001 0.001" />
            </geometry>
        </collision>
    </link>
    <link name="wheel_attachment_v5_4">
        <inertial>
            <origin rpy="0 0 0" xyz="1.4779825485700115e-07 -0.020183402397810468 3.2810090075385823e-07" />
            <mass value="2.8568879657816306" />
            <inertia ixx="0.0105" ixy="0.0" ixz="0.0" iyy="0.020703" iyz="0.0" izz="0.0105" />
        </inertial>
        <visual>
            <origin rpy="0 0 0" xyz="0.371916 0.220594 -0.101126" />
            <geometry>
                <mesh filename="package://agribot_v4_description/meshes/wheel_attachment_v5_4.stl" scale="0.001 0.001 0.001" />
            </geometry>
            <material name="steel_satin" />
        </visual>
        <collision>
            <origin rpy="0 0 0" xyz="0.371916 0.220594 -0.101126" />
            <geometry>
                <mesh filename="package://agribot_v4_description/meshes/wheel_attachment_v5_4.stl" scale="0.001 0.001 0.001" />
            </geometry>
        </collision>
    </link>
    <link name="camera_mount_v1_1">
        <inertial>
            <origin rpy="0 0 0" xyz="-0.4600002144925488 -0.010000109982663652 0.07788708172937764" />
            <mass value="0.5409900233067988" />
            <inertia ixx="0.000886" ixy="0.000133" ixz="0.0" iyy="0.00104" iyz="0.0" izz="0.00081" />
        </inertial>
        <visual>
            <origin rpy="0 0 0" xyz="-0.225 0.155 -0.555912" />
            <geometry>
                <mesh filename="package://agribot_v4_description/meshes/camera_mount_v1_1.stl" scale="0.001 0.001 0.001" />
            </geometry>
            <material name="steel_satin" />
        </visual>
        <collision>
            <origin rpy="0 0 0" xyz="-0.225 0.155 -0.555912" />
            <geometry>
                <mesh filename="package://agribot_v4_description/meshes/camera_mount_v1_1.stl" scale="0.001 0.001 0.001" />
            </geometry>
        </collision>
    </link>
    <link name="kinectv2_v1_1">
        <inertial>
            <origin rpy="0 0 0" xyz="-0.0022256530251535678 -0.0015280984272730835 0.038314148569505435" />
            <mass value="0.7810524514781609" />
            <inertia ixx="0.001347" ixy="0.001381" ixz="1.3e-05" iyy="0.00299" iyz="2e-05" izz="0.003916" />
        </inertial>
        <visual>
            <origin rpy="0 0 0" xyz="0.235 0.165 -0.655912" />
            <geometry>
                <mesh filename="package://agribot_v4_description/meshes/kinectv2_v1_1.stl" scale="0.001 0.001 0.001" />
            </geometry>
            <material name="silver_default" />
        </visual>
        <collision>
            <origin rpy="0 0 0" xyz="0.235 0.165 -0.655912" />
            <geometry>
                <mesh filename="package://agribot_v4_description/meshes/kinectv2_v1_1.stl" scale="0.001 0.001 0.001" />
            </geometry>
        </collision>
    </link>
    <link name="rgb_frame" />
    <joint name="kinect_rgb_frame" type="fixed">
        <parent link="kinectv2_v1_1" />
        <child link="rgb_frame" />
        <origin rpy="0 0 2.61799" xyz="0.075 0.00 0.0375" />
        <axis xyz="0 0 0" />
    </joint>
    <link name="optical_frame" />
    <joint name="rgb_optical_frame" type="fixed">
        <parent link="rgb_frame" />
        <child link="optical_frame" />
        <origin rpy="-1.5708 0 -1.5708" xyz="0 0 0" />
        <axis xyz="0 0 0" />
    </joint>
    <link name="base_arm_v2_1">
        <inertial>
            <origin rpy="0 0 0" xyz="0.009999785507459086 0.009999890017333729 0.010307185646813322" />
            <mass value="0.9330886709339293" />
            <inertia ixx="0.001421" ixy="0.0" ixz="0.0" iyy="0.001421" iyz="-0.0" izz="0.002578" />
        </inertial>
        <visual>
            <origin rpy="0 0 0" xyz="-0.225 -0.155 -0.555912" />
            <geometry>
                <mesh filename="package://agribot_v4_description/meshes/base_arm_v2_1.stl" scale="0.001 0.001 0.001" />
            </geometry>
            <material name="silver_default" />
        </visual>
        <collision>
            <origin rpy="0 0 0" xyz="-0.225 -0.155 -0.555912" />
            <geometry>
                <mesh filename="package://agribot_v4_description/meshes/base_arm_v2_1.stl" scale="0.001 0.001 0.001" />
            </geometry>
        </collision>
    </link>
    <link name="link_1_v3_1">
        <inertial>
            <origin rpy="0 0 0" xyz="-0.00327216143288786 0.004456568550276624 0.025593631697443775" />
            <mass value="1.6613467153005188" />
            <inertia ixx="0.002663" ixy="-2.2e-05" ixz="0.000339" iyy="0.002483" iyz="-0.000454" izz="0.002146" />
        </inertial>
        <visual>
            <origin rpy="0 0 0" xyz="-0.235 -0.165 -0.596912" />
            <geometry>
                <mesh filename="package://agribot_v4_description/meshes/link_1_v3_1.stl" scale="0.001 0.001 0.001" />
            </geometry>
            <material name="opaque272727" />
        </visual>
        <collision>
            <origin rpy="0 0 0" xyz="-0.235 -0.165 -0.596912" />
            <geometry>
                <mesh filename="package://agribot_v4_description/meshes/link_1_v3_1.stl" scale="0.001 0.001 0.001" />
            </geometry>
        </collision>
    </link>
    <link name="link_2_v1_1">
        <inertial>
            <origin rpy="0 0 0" xyz="-0.002499674374759231 0.05852735573072501 0.055083976110799404" />
            <mass value="0.2532575834482899" />
            <inertia ixx="0.000795" ixy="-0.0" ixz="-0.0" iyy="0.000454" iyz="-0.000362" izz="0.000342" />
        </inertial>
        <visual>
            <origin rpy="0 0 0" xyz="-0.229038 -0.206051 -0.671652" />
            <geometry>
                <mesh filename="package://agribot_v4_description/meshes/link_2_v1_1.stl" scale="0.001 0.001 0.001" />
            </geometry>
            <material name="steel_satin" />
        </visual>
        <collision>
            <origin rpy="0 0 0" xyz="-0.229038 -0.206051 -0.671652" />
            <geometry>
                <mesh filename="package://agribot_v4_description/meshes/link_2_v1_1.stl" scale="0.001 0.001 0.001" />
            </geometry>
        </collision>
    </link>
    <link name="link_3_v2_1">
        <inertial>
            <origin rpy="0 0 0" xyz="0.018953836847959454 0.03419498146288552 0.03607574562712246" />
            <mass value="0.6682248227150334" />
            <inertia ixx="0.002549" ixy="-6e-06" ixz="-7e-06" iyy="0.001313" iyz="-0.001236" izz="0.001356" />
        </inertial>
        <visual>
            <origin rpy="0 0 0" xyz="-0.229038 -0.325452 -0.791052" />
            <geometry>
                <mesh filename="package://agribot_v4_description/meshes/link_3_v2_1.stl" scale="0.001 0.001 0.001" />
            </geometry>
            <material name="silver_default" />
        </visual>
        <collision>
            <origin rpy="0 0 0" xyz="-0.229038 -0.325452 -0.791052" />
            <geometry>
                <mesh filename="package://agribot_v4_description/meshes/link_3_v2_1.stl" scale="0.001 0.001 0.001" />
            </geometry>
        </collision>
    </link>
    <link name="eef_base_v1_1">
        <inertial>
            <origin rpy="0 0 0" xyz="0.019106499239375407 0.027475210738584444 0.03359965921990549" />
            <mass value="0.33153308863416847" />
            <inertia ixx="9.1e-05" ixy="0.0" ixz="-1e-06" iyy="0.000111" iyz="-1.4e-05" izz="0.000102" />
        </inertial>
        <visual>
            <origin rpy="0 0 0" xyz="-0.229338 -0.415907 -0.881508" />
            <geometry>
                <mesh filename="package://agribot_v4_description/meshes/eef_base_v1_1.stl" scale="0.001 0.001 0.001" />
            </geometry>
            <material name="silver_default" />
        </visual>
        <collision>
            <origin rpy="0 0 0" xyz="-0.229338 -0.415907 -0.881508" />
            <geometry>
                <mesh filename="package://agribot_v4_description/meshes/eef_base_v1_1.stl" scale="0.001 0.001 0.001" />
            </geometry>
        </collision>
    </link>
    <link name="left_claw_v3_1">
        <inertial>
            <origin rpy="0 0 0" xyz="-0.062327211906866964 0.011880400089153864 0.013014001371863593" />
            <mass value="0.02736131598910003" />
            <inertia ixx="4e-06" ixy="6e-06" ixz="6e-06" iyy="2.5e-05" iyz="-2e-06" izz="2.4e-05" />
        </inertial>
        <visual>
            <origin rpy="0 0 0" xyz="-0.237848 -0.469218 -0.921444" />
            <geometry>
                <mesh filename="package://agribot_v4_description/meshes/left_claw_v3_1.stl" scale="0.001 0.001 0.001" />
            </geometry>
            <material name="silver_default" />
        </visual>
        <collision>
            <origin rpy="0 0 0" xyz="-0.237848 -0.469218 -0.921444" />
            <geometry>
                <mesh filename="package://agribot_v4_description/meshes/left_claw_v3_1.stl" scale="0.001 0.001 0.001" />
            </geometry>
        </collision>
    </link>
    <link name="right_claw_v3_1">
        <inertial>
            <origin rpy="0 0 0" xyz="0.062327872561855735 0.011885018645027445 0.01301861992772635" />
            <mass value="0.027361315989100486" />
            <inertia ixx="4e-06" ixy="-6e-06" ixz="-6e-06" iyy="2.5e-05" iyz="-2e-06" izz="2.4e-05" />
        </inertial>
        <visual>
            <origin rpy="0 0 0" xyz="-0.279848 -0.454369 -0.906595" />
            <geometry>
                <mesh filename="package://agribot_v4_description/meshes/right_claw_v3_1.stl" scale="0.001 0.001 0.001" />
            </geometry>
            <material name="silver_default" />
        </visual>
        <collision>
            <origin rpy="0 0 0" xyz="-0.279848 -0.454369 -0.906595" />
            <geometry>
                <mesh filename="package://agribot_v4_description/meshes/right_claw_v3_1.stl" scale="0.001 0.001 0.001" />
            </geometry>
        </collision>
    </link>
    <link name="ydlidar_x4_v1_1">
        <inertial>
            <origin rpy="0 0 0" xyz="0.006705685937131195 -1.0998266568054804e-07 0.020200983707366116" />
            <mass value="1.1515616542314233" />
            <inertia ixx="0.000489" ixy="0.0" ixz="-0.000148" iyy="0.000861" iyz="-0.0" izz="0.000987" />
        </inertial>
        <visual>
            <origin rpy="0 0 0" xyz="0.25 0.0 -0.585912" />
            <geometry>
                <mesh filename="package://agribot_v4_description/meshes/ydlidar_x4_v1_1.stl" scale="0.001 0.001 0.001" />
            </geometry>
            <material name="steel_satin" />
        </visual>
        <collision>
            <origin rpy="0 0 0" xyz="0.25 0.0 -0.555912" />
            <geometry>
                <mesh filename="package://agribot_v4_description/meshes/ydlidar_x4_v1_1.stl" scale="0.001 0.001 0.001" />
            </geometry>
        </collision>
    </link>
    <joint name="front_right_steer" type="continuous">
        <origin rpy="0 0 0" xyz="0.372581 -0.24075 0.2316" />
        <parent link="base_link" />
        <child link="wheel_steer_v2_1" />
        <axis xyz="0.002015 0.0 -0.999998" />
    </joint>
    <joint name="front_left_steer" type="continuous">
        <origin rpy="0 0 0" xyz="0.372522 0.24115 0.231574" />
        <parent link="base_link" />
        <child link="wheel_steer_v2_2" />
        <axis xyz="0.001375 0.0 -0.999999" />
    </joint>
    <joint name="back_right_steer" type="continuous">
        <origin rpy="0 0 0" xyz="-0.371732 -0.24115 0.231126" />
        <parent link="base_link" />
        <child link="wheel_steer_v2_3" />
        <axis xyz="-0.001415 0.0 -0.999999" />
    </joint>
    <joint name="back_left_steer" type="continuous">
        <origin rpy="0 0 0" xyz="-0.372163 0.24115 0.231127" />
        <parent link="base_link" />
        <child link="wheel_steer_v2_4" />
        <axis xyz="-0.001415 0.0 -0.999999" />
    </joint>
    <joint name="front_right_drive" type="continuous">
        <origin rpy="0 0 0" xyz="0.000261 0.020556 -0.13" />
        <parent link="wheel_steer_v2_1" />
        <child link="wheel_attachment_v5_1" />
        <axis xyz="0.0 1.0 -0.0" />
    </joint>
    <joint name="front_left_drive" type="continuous">
        <origin rpy="0 0 0" xyz="0.000179 -0.020557 -0.13" />
        <parent link="wheel_steer_v2_2" />
        <child link="wheel_attachment_v5_2" />
        <axis xyz="-0.0 1.0 0.0" />
    </joint>
    <joint name="back_left_drive" type="continuous">
        <origin rpy="0 0 0" xyz="-0.000183 -0.020557 -0.13" />
        <parent link="wheel_steer_v2_4" />
        <child link="wheel_attachment_v5_3" />
        <axis xyz="-0.0 1.0 0.0" />
    </joint>
    <joint name="back_right_drive" type="continuous">
        <origin rpy="0 0 0" xyz="-0.000184 0.020556 -0.13" />
        <parent link="wheel_steer_v2_3" />
        <child link="wheel_attachment_v5_4" />
        <axis xyz="0.0 1.0 -0.0" />
    </joint>
    <joint name="Rigid 9" type="fixed">
        <origin rpy="0 0 0" xyz="0.225 -0.155 0.555912" />
        <parent link="base_link" />
        <child link="camera_mount_v1_1" />
    </joint>
    <joint name="Rigid 10" type="fixed">
        <origin rpy="0 0 0" xyz="-0.46 -0.01 0.1" />
        <parent link="camera_mount_v1_1" />
        <child link="kinectv2_v1_1" />
    </joint>
    <joint name="Rigid 11" type="fixed">
        <origin rpy="0 0 0" xyz="0.225 0.155 0.555912" />
        <parent link="base_link" />
        <child link="base_arm_v2_1" />
    </joint>
    <joint name="base_twist" type="continuous">
        <origin rpy="0 0 0" xyz="0.01 0.01 0.041" />
        <parent link="base_arm_v2_1" />
        <child link="link_1_v3_1" />
        <axis xyz="-0.0 0.0 -1.0" />
    </joint>
    <joint name="shoulder" type="continuous">
        <origin rpy="0 0 0" xyz="-0.005962 0.041051 0.07474" />
        <parent link="link_1_v3_1" />
        <child link="link_2_v1_1" />
        <axis xyz="1.0 0.0 -0.0" />
    </joint>
    <joint name="elbow" type="continuous">
        <origin rpy="0 0 0" xyz="0.0 0.119401 0.1194" />
        <parent link="link_2_v1_1" />
        <child link="link_3_v2_1" />
        <axis xyz="1.0 -0.0 -0.0" />
    </joint>
    <joint name="wrist" type="continuous">
        <origin rpy="0 0 0" xyz="0.0003 0.090455 0.090456" />
        <parent link="link_3_v2_1" />
        <child link="eef_base_v1_1" />
        <axis xyz="-1.0 0.0 0.0" />
    </joint>
    <joint name="left_grip" type="continuous">
        <origin rpy="0 0 0" xyz="-0.01249 0.038462 0.025087" />
        <parent link="eef_base_v1_1" />
        <child link="left_claw_v3_1" />
        <axis xyz="0.0 -0.707107 0.707107" />
    </joint>
    <joint name="right_grip" type="continuous">
        <origin rpy="0 0 0" xyz="0.05051 0.038462 0.025087" />
        <parent link="eef_base_v1_1" />
        <child link="right_claw_v3_1" />
        <axis xyz="0.0 -0.707107 0.707107" />
    </joint>
    <joint name="Rigid 18" type="fixed">
        <origin rpy="0 0 0" xyz="-0.25 0.0 0.585912" />
        <parent link="base_link" />
        <child link="ydlidar_x4_v1_1" />
    </joint>
</robot>

